[2025-04-11 23:53:14 +0000] [496] [ERROR] Exception in worker process
Traceback (most recent call last):
  File "/home/runner/workspace/.pythonlibs/lib/python3.11/site-packages/gunicorn/arbiter.py", line 608, in spawn_worker
    worker.init_process()
  File "/home/runner/workspace/.pythonlibs/lib/python3.11/site-packages/gunicorn/workers/base.py", line 135, in init_process
    self.load_wsgi()
  File "/home/runner/workspace/.pythonlibs/lib/python3.11/site-packages/gunicorn/workers/base.py", line 147, in load_wsgi
    self.wsgi = self.app.wsgi()
                ^^^^^^^^^^^^^^^
  File "/home/runner/workspace/.pythonlibs/lib/python3.11/site-packages/gunicorn/app/base.py", line 66, in wsgi
    self.callable = self.load()
                    ^^^^^^^^^^^
  File "/home/runner/workspace/.pythonlibs/lib/python3.11/site-packages/gunicorn/app/wsgiapp.py", line 57, in load
    return self.load_wsgiapp()
           ^^^^^^^^^^^^^^^^^^^
  File "/home/runner/workspace/.pythonlibs/lib/python3.11/site-packages/gunicorn/app/wsgiapp.py", line 47, in load_wsgiapp
    return util.import_app(self.app_uri)
           ^^^^^^^^^^^^^^^^^^^^^^^^^^^^^
  File "/home/runner/workspace/.pythonlibs/lib/python3.11/site-packages/gunicorn/util.py", line 370, in import_app
    mod = importlib.import_module(module)
          ^^^^^^^^^^^^^^^^^^^^^^^^^^^^^^^
  File "/nix/store/clx0mcir7qw8zk36zbr4jra789g3knf6-python3-3.11.10/lib/python3.11/importlib/__init__.py", line 126, in import_module
    return _bootstrap._gcd_import(name[level:], package, level)
           ^^^^^^^^^^^^^^^^^^^^^^^^^^^^^^^^^^^^^^^^^^^^^^^^^^^^
  File "<frozen importlib._bootstrap>", line 1204, in _gcd_import
  File "<frozen importlib._bootstrap>", line 1176, in _find_and_load
  File "<frozen importlib._bootstrap>", line 1147, in _find_and_load_unlocked
  File "<frozen importlib._bootstrap>", line 690, in _load_unlocked
  File "<frozen importlib._bootstrap_external>", line 940, in exec_module
  File "<frozen importlib._bootstrap>", line 241, in _call_with_frames_removed
  File "/home/runner/workspace/main.py", line 1, in <module>
    from app import app
  File "/home/runner/workspace/app.py", line 58, in <module>
    app = create_app()
          ^^^^^^^^^^^^
  File "/home/runner/workspace/app.py", line 31, in create_app
    db.init_app(app)
  File "/home/runner/workspace/.pythonlibs/lib/python3.11/site-packages/flask_sqlalchemy/extension.py", line 374, in init_app
    engines[key] = self._make_engine(key, options, app)
                   ^^^^^^^^^^^^^^^^^^^^^^^^^^^^^^^^^^^^
  File "/home/runner/workspace/.pythonlibs/lib/python3.11/site-packages/flask_sqlalchemy/extension.py", line 665, in _make_engine
    return sa.engine_from_config(options, prefix="")
           ^^^^^^^^^^^^^^^^^^^^^^^^^^^^^^^^^^^^^^^^^
  File "/home/runner/workspace/.pythonlibs/lib/python3.11/site-packages/sqlalchemy/engine/create.py", line 823, in engine_from_config
    return create_engine(url, **options)
           ^^^^^^^^^^^^^^^^^^^^^^^^^^^^^
  File "<string>", line 2, in create_engine
  File "/home/runner/workspace/.pythonlibs/lib/python3.11/site-packages/sqlalchemy/util/deprecations.py", line 281, in warned
    return fn(*args, **kwargs)  # type: ignore[no-any-return]
           ^^^^^^^^^^^^^^^^^^^
  File "/home/runner/workspace/.pythonlibs/lib/python3.11/site-packages/sqlalchemy/engine/create.py", line 602, in create_engine
    dbapi = dbapi_meth(**dbapi_args)
            ^^^^^^^^^^^^^^^^^^^^^^^^
  File "/home/runner/workspace/.pythonlibs/lib/python3.11/site-packages/sqlalchemy/dialects/mysql/mysqldb.py", line 149, in import_dbapi
    return __import__("MySQLdb")
           ^^^^^^^^^^^^^^^^^^^^^
ModuleNotFoundError: No module named 'MySQLdb'
[2025-04-11 23:53:14 +0000] [496] [INFO] Worker exiting (pid: 496)
[2025-04-11 23:53:14 +0000] [484] [ERROR] Worker (pid:496) exited with code 3
[2025-04-11 23:53:14 +0000] [484] [ERROR] Shutting down: Master
[2025-04-11 23:53:14 +0000] [484] [ERROR] Reason: Worker failed to boot.
