INFO:werkzeug:172.31.128.18 - - [12/Apr/2025 10:13:49] "GET /tourist/book_tour/2?date=2025-04-22&people=1 HTTP/1.1" 200 -
INFO:werkzeug:172.31.128.18 - - [12/Apr/2025 10:14:21] "POST /tourist/book_tour/2?date=2025-04-22&people=1 HTTP/1.1" 500 -
Traceback (most recent call last):
  File "/home/runner/workspace/.pythonlibs/lib/python3.11/site-packages/flask/app.py", line 1536, in __call__
    return self.wsgi_app(environ, start_response)
           ^^^^^^^^^^^^^^^^^^^^^^^^^^^^^^^^^^^^^^
  File "/home/runner/workspace/.pythonlibs/lib/python3.11/site-packages/flask/app.py", line 1514, in wsgi_app
    response = self.handle_exception(e)
               ^^^^^^^^^^^^^^^^^^^^^^^^
  File "/home/runner/workspace/.pythonlibs/lib/python3.11/site-packages/flask/app.py", line 1511, in wsgi_app
    response = self.full_dispatch_request()
               ^^^^^^^^^^^^^^^^^^^^^^^^^^^^
  File "/home/runner/workspace/.pythonlibs/lib/python3.11/site-packages/flask/app.py", line 919, in full_dispatch_request
    rv = self.handle_user_exception(e)
         ^^^^^^^^^^^^^^^^^^^^^^^^^^^^^
  File "/home/runner/workspace/.pythonlibs/lib/python3.11/site-packages/flask/app.py", line 917, in full_dispatch_request
    rv = self.dispatch_request()
         ^^^^^^^^^^^^^^^^^^^^^^^
  File "/home/runner/workspace/.pythonlibs/lib/python3.11/site-packages/flask/app.py", line 902, in dispatch_request
    return self.ensure_sync(self.view_functions[rule.endpoint])(**view_args)  # type: ignore[no-any-return]
           ^^^^^^^^^^^^^^^^^^^^^^^^^^^^^^^^^^^^^^^^^^^^^^^^^^^^^^^^^^^^^^^^^^^^^^^^^^^^^^^^^^^^^^^^^^^^^^^^
  File "/home/runner/workspace/.pythonlibs/lib/python3.11/site-packages/flask_login/utils.py", line 290, in decorated_view
    return current_app.ensure_sync(func)(*args, **kwargs)
           ^^^^^^^^^^^^^^^^^^^^^^^^^^^^^^^^^^^^^^^^^^^^^^
  File "/home/runner/workspace/routes.py", line 788, in book_tour
    booking = TourBooking(
              ^^^^^^^^^^^^
  File "<string>", line 4, in __init__
  File "/home/runner/workspace/.pythonlibs/lib/python3.11/site-packages/sqlalchemy/orm/state.py", line 571, in _initialize_instance
    with util.safe_reraise():
  File "/home/runner/workspace/.pythonlibs/lib/python3.11/site-packages/sqlalchemy/util/langhelpers.py", line 146, in __exit__
    raise exc_value.with_traceback(exc_tb)
  File "/home/runner/workspace/.pythonlibs/lib/python3.11/site-packages/sqlalchemy/orm/state.py", line 569, in _initialize_instance
    manager.original_init(*mixed[1:], **kwargs)
  File "/home/runner/workspace/.pythonlibs/lib/python3.11/site-packages/sqlalchemy/orm/decl_base.py", line 2175, in _declarative_constructor
    raise TypeError(
TypeError: 'number_of_people' is an invalid keyword argument for TourBooking
INFO:werkzeug:172.31.128.18 - - [12/Apr/2025 10:14:21] "GET /tourist/book_tour/2?__debugger__=yes&cmd=resource&f=style.css HTTP/1.1" 304 -
INFO:werkzeug:172.31.128.18 - - [12/Apr/2025 10:14:22] "GET /tourist/book_tour/2?__debugger__=yes&cmd=resource&f=debugger.js HTTP/1.1" 304 -
INFO:werkzeug:172.31.128.18 - - [12/Apr/2025 10:14:22] "GET /tourist/book_tour/2?__debugger__=yes&cmd=resource&f=console.png HTTP/1.1" 304 -
